Workbook

Sheet Executive_Dashboard
A1: NEXTHIKES IT SOLUTIONS | BIKE SHARING DEMAND EXECUTIVE DASHBOARD
A2: Operational Business Intelligence, Fleet Rebalancing & AI Forecasting | Submitted by Ritesh Saroj
A4: TOTAL BIKE RENTALS | C4: REGISTERED COMMUTERS | E4: CASUAL LEISURE RIDERS | G4: AVERAGE HOURLY DEMAND | I4: PEAK RECORDED DEMAND | K4: PEAK COMMUTE SURGE | M4: THERMAL DEMAND LIFT
A5: =SUM(Master_Cleaned_Data!W5:W1004) -> 58304 | C5: =SUM(Master_Cleaned_Data!V5:V1004) -> 53383 | E5: =SUM(Master_Cleaned_Data!U5:U1004) -> 4921 | G5: =ROUND(AVERAGE(Master_Cleaned_Data!W5:W1004), 1) -> 58.3 | I5: =MAX(Master_Cleaned_Data!W5:W1004) -> 249 | K5: =ROUND(AVERAGEIF(Master_Cleaned_Data!L5:L1004, "Peak Commute", Master_Cleaned_Data!W5:W1004), 1) -> 135.5 | M5: =(AVERAGEIF(Master_Cleaned_Data!O5:O1004, ">0.28", Master_Cleaned_Data!W5:W1004) - AVERAGEIF(Master_Cleaned_Data!O5:O1004, "<=0.22", Master_Cleaned_Data!W5:W1004)) / AVERAGEIF(Master_Cleaned_Data!O5:O1004, "<=0.22", Master_Cleaned_Data!W5:W1004) -> 0.67656074
A6: Total Demand (1,000 Hours) | C6: 91.6% of Total Ridership | E6: 8.4% Pay-Per-Ride | G6: ±51.0 Rides/Hr Volatility | I6: Record: Thu 17:00 (Inst #440) | K6: Rush Hours (07-09 & 17-19) | M6: Hot (86) vs Cold (51) Lift
A27: Operational Demand Heatmap: Hour of Day vs Day of Week (Rides / Hr) | K27: Weather Severity Impact Analysis
A28: Hour | B28: Sunday | C28: Monday | D28: Tuesday | E28: Wednesday | F28: Thursday | G28: Friday | H28: Saturday | I28: 24-Hr Avg | K28: Weather Category | L28: Hours | M28: Average Demand | N28: Volume Impact
A29: 00:00 | B29: =AVERAGEIFS(Master_Cleaned_Data!$W$5:$W$1004, Master_Cleaned_Data!$G$5:$G$1004, 0, Master_Cleaned_Data!$I$5:$I$1004, 0) -> 30.571429 | C29: =AVERAGEIFS(Master_Cleaned_Data!$W$5:$W$1004, Master_Cleaned_Data!$G$5:$G$1004, 0, Master_Cleaned_Data!$I$5:$I$1004, 1) -> 9.5714286 | D29: =AVERAGEIFS(Master_Cleaned_Data!$W$5:$W$1004, Master_Cleaned_Data!$G$5:$G$1004, 0, Master_Cleaned_Data!$I$5:$I$1004, 2) -> 8.8 | E29: =AVERAGEIFS(Master_Cleaned_Data!$W$5:$W$1004, Master_Cleaned_Data!$G$5:$G$1004, 0, Master_Cleaned_Data!$I$5:$I$1004, 3) -> 8.6666667 | F29: =AVERAGEIFS(Master_Cleaned_Data!$W$5:$W$1004, Master_Cleaned_Data!$G$5:$G$1004, 0, Master_Cleaned_Data!$I$5:$I$1004, 4) -> 11.8 | G29: =AVERAGEIFS(Master_Cleaned_Data!$W$5:$W$1004, Master_Cleaned_Data!$G$5:$G$1004, 0, Master_Cleaned_Data!$I$5:$I$1004, 5) -> 14.666667 | H29: =AVERAGEIFS(Master_Cleaned_Data!$W$5:$W$1004, Master_Cleaned_Data!$G$5:$G$1004, 0, Master_Cleaned_Data!$I$5:$I$1004, 6) -> 25.571429 | I29: =AVERAGE(B29:H29) -> 15.663946 | K29: Clear / Few Clouds | L29: =COUNTIF(Master_Cleaned_Data!$M$5:$M$1004, 1) -> 606 | M29: =AVERAGEIF(Master_Cleaned_Data!$M$5:$M$1004, 1, Master_Cleaned_Data!$W$5:$W$1004) -> 61.671617 | N29: =(M29-M$29)/M$29 -> 0
A30: 01:00 | B30: =AVERAGEIFS(Master_Cleaned_Data!$W$5:$W$1004, Master_Cleaned_Data!$G$5:$G$1004, 1, Master_Cleaned_Data!$I$5:$I$1004, 0) -> 23.142857 | C30: =AVERAGEIFS(Master_Cleaned_Data!$W$5:$W$1004, Master_Cleaned_Data!$G$5:$G$1004, 1, Master_Cleaned_Data!$I$5:$I$1004, 1) -> 5.5714286 | D30: =AVERAGEIFS(Master_Cleaned_Data!$W$5:$W$1004, Master_Cleaned_Data!$G$5:$G$1004, 1, Master_Cleaned_Data!$I$5:$I$1004, 2) -> 3.4 | E30: =AVERAGEIFS(Master_Cleaned_Data!$W$5:$W$1004, Master_Cleaned_Data!$G$5:$G$1004, 1, Master_Cleaned_Data!$I$5:$I$1004, 3) -> 5.6666667 | F30: =AVERAGEIFS(Master_Cleaned_Data!$W$5:$W$1004, Master_Cleaned_Data!$G$5:$G$1004, 1, Master_Cleaned_Data!$I$5:$I$1004, 4) -> 4.6 | G30: =AVERAGEIFS(Master_Cleaned_Data!$W$5:$W$1004, Master_Cleaned_Data!$G$5:$G$1004, 1, Master_Cleaned_Data!$I$5:$I$1004, 5) -> 5.8333333 | H30: =AVERAGEIFS(Master_Cleaned_Data!$W$5:$W$1004, Master_Cleaned_Data!$G$5:$G$1004, 1, Master_Cleaned_Data!$I$5:$I$1004, 6) -> 21.428571 | I30: =AVERAGE(B30:H30) -> 9.9489796 | K30: Mist / Cloudy | L30: =COUNTIF(Master_Cleaned_Data!$M$5:$M$1004, 2) -> 309 | M30: =AVERAGEIF(Master_Cleaned_Data!$M$5:$M$1004, 2, Master_Cleaned_Data!$W$5:$W$1004) -> 58.595469 | N30: =(M30-M$29)/M$29 -> -0.049879475
A31: 02:00 | B31: =AVERAGEIFS(Master_Cleaned_Data!$W$5:$W$1004, Master_Cleaned_Data!$G$5:$G$1004, 2, Master_Cleaned_Data!$I$5:$I$1004, 0) -> 15 | C31: =AVERAGEIFS(Master_Cleaned_Data!$W$5:$W$1004, Master_Cleaned_Data!$G$5:$G$1004, 2, Master_Cleaned_Data!$I$5:$I$1004, 1) -> 3.4 | D31: =AVERAGEIFS(Master_Cleaned_Data!$W$5:$W$1004, Master_Cleaned_Data!$G$5:$G$1004, 2, Master_Cleaned_Data!$I$5:$I$1004, 2) -> 2 | E31: =AVERAGEIFS(Master_Cleaned_Data!$W$5:$W$1004, Master_Cleaned_Data!$G$5:$G$1004, 2, Master_Cleaned_Data!$I$5:$I$1004, 3) -> 3.8333333 | F31: =AVERAGEIFS(Master_Cleaned_Data!$W$5:$W$1004, Master_Cleaned_Data!$G$5:$G$1004, 2, Master_Cleaned_Data!$I$5:$I$1004, 4) -> 2.2 | G31: =AVERAGEIFS(Master_Cleaned_Data!$W$5:$W$1004, Master_Cleaned_Data!$G$5:$G$1004, 2, Master_Cleaned_Data!$I$5:$I$1004, 5) -> 1.6666667 | H31: =AVERAGEIFS(Master_Cleaned_Data!$W$5:$W$1004, Master_Cleaned_Data!$G$5:$G$1004, 2, Master_Cleaned_Data!$I$5:$I$1004, 6) -> 16.857143 | I31: =AVERAGE(B31:H31) -> 6.422449 | K31: Light Snow / Rain | L31: =COUNTIF(Master_Cleaned_Data!$M$5:$M$1004, 3) -> 84 | M31: =AVERAGEIF(Master_Cleaned_Data!$M$5:$M$1004, 3, Master_Cleaned_Data!$W$5:$W$1004) -> 33.202381 | N31: =(M31-M$29)/M$29 -> -0.46162623
A32: 03:00 | B32: =AVERAGEIFS(Master_Cleaned_Data!$W$5:$W$1004, Master_Cleaned_Data!$G$5:$G$1004, 3, Master_Cleaned_Data!$I$5:$I$1004, 0) -> 9 | C32: =AVERAGEIFS(Master_Cleaned_Data!$W$5:$W$1004, Master_Cleaned_Data!$G$5:$G$1004, 3, Master_Cleaned_Data!$I$5:$I$1004, 1) -> 1.5 | D32: =AVERAGEIFS(Master_Cleaned_Data!$W$5:$W$1004, Master_Cleaned_Data!$G$5:$G$1004, 3, Master_Cleaned_Data!$I$5:$I$1004, 2) -> 1.5 | E32: =AVERAGEIFS(Master_Cleaned_Data!$W$5:$W$1004, Master_Cleaned_Data!$G$5:$G$1004, 3, Master_Cleaned_Data!$I$5:$I$1004, 3) -> 1.5 | F32: =AVERAGEIFS(Master_Cleaned_Data!$W$5:$W$1004, Master_Cleaned_Data!$G$5:$G$1004, 3, Master_Cleaned_Data!$I$5:$I$1004, 4) -> 1.6666667 | G32: =AVERAGEIFS(Master_Cleaned_Data!$W$5:$W$1004, Master_Cleaned_Data!$G$5:$G$1004, 3, Master_Cleaned_Data!$I$5:$I$1004, 5) -> 1 | H32: =AVERAGEIFS(Master_Cleaned_Data!$W$5:$W$1004, Master_Cleaned_Data!$G$5:$G$1004, 3, Master_Cleaned_Data!$I$5:$I$1004, 6) -> 9.1428571 | I32: =AVERAGE(B32:H32) -> 3.6156463 | K32: Heavy Rain / Ice | L32: =COUNTIF(Master_Cleaned_Data!$M$5:$M$1004, 4) -> 1 | M32: =AVERAGEIF(Master_Cleaned_Data!$M$5:$M$1004, 4, Master_Cleaned_Data!$W$5:$W$1004) -> 36 | N32: =(M32-M$29)/M$29 -> -0.41626308
A33: 04:00 | B33: =AVERAGEIFS(Master_Cleaned_Data!$W$5:$W$1004, Master_Cleaned_Data!$G$5:$G$1004, 4, Master_Cleaned_Data!$I$5:$I$1004, 0) -> 1.6666667 | C33: =AVERAGEIFS(Master_Cleaned_Data!$W$5:$W$1004, Master_Cleaned_Data!$G$5:$G$1004, 4, Master_Cleaned_Data!$I$5:$I$1004, 1) -> 2 | D33: =AVERAGEIFS(Master_Cleaned_Data!$W$5:$W$1004, Master_Cleaned_Data!$G$5:$G$1004, 4, Master_Cleaned_Data!$I$5:$I$1004, 2) -> 2 | E33: =AVERAGEIFS(Master_Cleaned_Data!$W$5:$W$1004, Master_Cleaned_Data!$G$5:$G$1004, 4, Master_Cleaned_Data!$I$5:$I$1004, 3) -> 1.6666667 | F33: =AVERAGEIFS(Master_Cleaned_Data!$W$5:$W$1004, Master_Cleaned_Data!$G$5:$G$1004, 4, Master_Cleaned_Data!$I$5:$I$1004, 4) -> 1.75 | G33: =AVERAGEIFS(Master_Cleaned_Data!$W$5:$W$1004, Master_Cleaned_Data!$G$5:$G$1004, 4, Master_Cleaned_Data!$I$5:$I$1004, 5) -> 1 | H33: =AVERAGEIFS(Master_Cleaned_Data!$W$5:$W$1004, Master_Cleaned_Data!$G$5:$G$1004, 4, Master_Cleaned_Data!$I$5:$I$1004, 6) -> 3.5714286 | I33: =AVERAGE(B33:H33) -> 1.9506803 | K33: Total Network | L33: =SUM(L29:L32) -> 1000 | M33: =AVERAGE(Master_Cleaned_Data!W5:W1004) -> 58.304 | N33: -
A34: 05:00 | B34: =AVERAGEIFS(Master_Cleaned_Data!$W$5:$W$1004, Master_Cleaned_Data!$G$5:$G$1004, 5, Master_Cleaned_Data!$I$5:$I$1004, 0) -> 2 | C34: =AVERAGEIFS(Master_Cleaned_Data!$W$5:$W$1004, Master_Cleaned_Data!$G$5:$G$1004, 5, Master_Cleaned_Data!$I$5:$I$1004, 1) -> 4.7142857 | D34: =AVERAGEIFS(Master_Cleaned_Data!$W$5:$W$1004, Master_Cleaned_Data!$G$5:$G$1004, 5, Master_Cleaned_Data!$I$5:$I$1004, 2) -> 4.8 | E34: =AVERAGEIFS(Master_Cleaned_Data!$W$5:$W$1004, Master_Cleaned_Data!$G$5:$G$1004, 5, Master_Cleaned_Data!$I$5:$I$1004, 3) -> 4.3333333 | F34: =AVERAGEIFS(Master_Cleaned_Data!$W$5:$W$1004, Master_Cleaned_Data!$G$5:$G$1004, 5, Master_Cleaned_Data!$I$5:$I$1004, 4) -> 4.2 | G34: =AVERAGEIFS(Master_Cleaned_Data!$W$5:$W$1004, Master_Cleaned_Data!$G$5:$G$1004, 5, Master_Cleaned_Data!$I$5:$I$1004, 5) -> 5.5 | H34: =AVERAGEIFS(Master_Cleaned_Data!$W$5:$W$1004, Master_Cleaned_Data!$G$5:$G$1004, 5, Master_Cleaned_Data!$I$5:$I$1004, 6) -> 3.4 | I34: =AVERAGE(B34:H34) -> 4.1353741
A35: 06:00 | B35: =AVERAGEIFS(Master_Cleaned_Data!$W$5:$W$1004, Master_Cleaned_Data!$G$5:$G$1004, 6, Master_Cleaned_Data!$I$5:$I$1004, 0) -> 1.8333333 | C35: =AVERAGEIFS(Master_Cleaned_Data!$W$5:$W$1004, Master_Cleaned_Data!$G$5:$G$1004, 6, Master_Cleaned_Data!$I$5:$I$1004, 1) -> 24.857143 | D35: =AVERAGEIFS(Master_Cleaned_Data!$W$5:$W$1004, Master_Cleaned_Data!$G$5:$G$1004, 6, Master_Cleaned_Data!$I$5:$I$1004, 2) -> 32 | E35: =AVERAGEIFS(Master_Cleaned_Data!$W$5:$W$1004, Master_Cleaned_Data!$G$5:$G$1004, 6, Master_Cleaned_Data!$I$5:$I$1004, 3) -> 25 | F35: =AVERAGEIFS(Master_Cleaned_Data!$W$5:$W$1004, Master_Cleaned_Data!$G$5:$G$1004, 6, Master_Cleaned_Data!$I$5:$I$1004, 4) -> 32.8 | G35: =AVERAGEIFS(Master_Cleaned_Data!$W$5:$W$1004, Master_Cleaned_Data!$G$5:$G$1004, 6, Master_Cleaned_Data!$I$5:$I$1004, 5) -> 24.333333 | H35: =AVERAGEIFS(Master_Cleaned_Data!$W$5:$W$1004, Master_Cleaned_Data!$G$5:$G$1004, 6, Master_Cleaned_Data!$I$5:$I$1004, 6) -> 2.4285714 | I35: =AVERAGE(B35:H35) -> 20.464626
A36: 07:00 | B36: =AVERAGEIFS(Master_Cleaned_Data!$W$5:$W$1004, Master_Cleaned_Data!$G$5:$G$1004, 7, Master_Cleaned_Data!$I$5:$I$1004, 0) -> 3.7142857 | C36: =AVERAGEIFS(Master_Cleaned_Data!$W$5:$W$1004, Master_Cleaned_Data!$G$5:$G$1004, 7, Master_Cleaned_Data!$I$5:$I$1004, 1) -> 71.857143 | D36: =AVERAGEIFS(Master_Cleaned_Data!$W$5:$W$1004, Master_Cleaned_Data!$G$5:$G$1004, 7, Master_Cleaned_Data!$I$5:$I$1004, 2) -> 90.6 | E36: =AVERAGEIFS(Master_Cleaned_Data!$W$5:$W$1004, Master_Cleaned_Data!$G$5:$G$1004, 7, Master_Cleaned_Data!$I$5:$I$1004, 3) -> 68.333333 | F36: =AVERAGEIFS(Master_Cleaned_Data!$W$5:$W$1004, Master_Cleaned_Data!$G$5:$G$1004, 7, Master_Cleaned_Data!$I$5:$I$1004, 4) -> 90.8 | G36: =AVERAGEIFS(Master_Cleaned_Data!$W$5:$W$1004, Master_Cleaned_Data!$G$5:$G$1004, 7, Master_Cleaned_Data!$I$5:$I$1004, 5) -> 73.833333 | H36: =AVERAGEIFS(Master_Cleaned_Data!$W$5:$W$1004, Master_Cleaned_Data!$G$5:$G$1004, 7, Master_Cleaned_Data!$I$5:$I$1004, 6) -> 7.1428571 | I36: =AVERAGE(B36:H36) -> 58.040136
A37: 08:00 | B37: =AVERAGEIFS(Master_Cleaned_Data!$W$5:$W$1004, Master_Cleaned_Data!$G$5:$G$1004, 8, Master_Cleaned_Data!$I$5:$I$1004, 0) -> 14.571429 | C37: =AVERAGEIFS(Master_Cleaned_Data!$W$5:$W$1004, Master_Cleaned_Data!$G$5:$G$1004, 8, Master_Cleaned_Data!$I$5:$I$1004, 1) -> 161.16667 | D37: =AVERAGEIFS(Master_Cleaned_Data!$W$5:$W$1004, Master_Cleaned_Data!$G$5:$G$1004, 8, Master_Cleaned_Data!$I$5:$I$1004, 2) -> 202.4 | E37: =AVERAGEIFS(Master_Cleaned_Data!$W$5:$W$1004, Master_Cleaned_Data!$G$5:$G$1004, 8, Master_Cleaned_Data!$I$5:$I$1004, 3) -> 157.66667 | F37: =AVERAGEIFS(Master_Cleaned_Data!$W$5:$W$1004, Master_Cleaned_Data!$G$5:$G$1004, 8, Master_Cleaned_Data!$I$5:$I$1004, 4) -> 207.2 | G37: =AVERAGEIFS(Master_Cleaned_Data!$W$5:$W$1004, Master_Cleaned_Data!$G$5:$G$1004, 8, Master_Cleaned_Data!$I$5:$I$1004, 5) -> 196.33333 | H37: =AVERAGEIFS(Master_Cleaned_Data!$W$5:$W$1004, Master_Cleaned_Data!$G$5:$G$1004, 8, Master_Cleaned_Data!$I$5:$I$1004, 6) -> 21 | I37: =AVERAGE(B37:H37) -> 137.19116
A38: 09:00 | B38: =AVERAGEIFS(Master_Cleaned_Data!$W$5:$W$1004, Master_Cleaned_Data!$G$5:$G$1004, 9, Master_Cleaned_Data!$I$5:$I$1004, 0) -> 32.714286 | C38: =AVERAGEIFS(Master_Cleaned_Data!$W$5:$W$1004, Master_Cleaned_Data!$G$5:$G$1004, 9, Master_Cleaned_Data!$I$5:$I$1004, 1) -> 93.5 | D38: =AVERAGEIFS(Master_Cleaned_Data!$W$5:$W$1004, Master_Cleaned_Data!$G$5:$G$1004, 9, Master_Cleaned_Data!$I$5:$I$1004, 2) -> 125 | E38: =AVERAGEIFS(Master_Cleaned_Data!$W$5:$W$1004, Master_Cleaned_Data!$G$5:$G$1004, 9, Master_Cleaned_Data!$I$5:$I$1004, 3) -> 101.5 | F38: =AVERAGEIFS(Master_Cleaned_Data!$W$5:$W$1004, Master_Cleaned_Data!$G$5:$G$1004, 9, Master_Cleaned_Data!$I$5:$I$1004, 4) -> 131.8 | G38: =AVERAGEIFS(Master_Cleaned_Data!$W$5:$W$1004, Master_Cleaned_Data!$G$5:$G$1004, 9, Master_Cleaned_Data!$I$5:$I$1004, 5) -> 130.83333 | H38: =AVERAGEIFS(Master_Cleaned_Data!$W$5:$W$1004, Master_Cleaned_Data!$G$5:$G$1004, 9, Master_Cleaned_Data!$I$5:$I$1004, 6) -> 29.142857 | I38: =AVERAGE(B38:H38) -> 92.070068
A39: 10:00 | B39: =AVERAGEIFS(Master_Cleaned_Data!$W$5:$W$1004, Master_Cleaned_Data!$G$5:$G$1004, 10, Master_Cleaned_Data!$I$5:$I$1004, 0) -> 71 | C39: =AVERAGEIFS(Master_Cleaned_Data!$W$5:$W$1004, Master_Cleaned_Data!$G$5:$G$1004, 10, Master_Cleaned_Data!$I$5:$I$1004, 1) -> 49.333333 | D39: =AVERAGEIFS(Master_Cleaned_Data!$W$5:$W$1004, Master_Cleaned_Data!$G$5:$G$1004, 10, Master_Cleaned_Data!$I$5:$I$1004, 2) -> 49.2 | E39: =AVERAGEIFS(Master_Cleaned_Data!$W$5:$W$1004, Master_Cleaned_Data!$G$5:$G$1004, 10, Master_Cleaned_Data!$I$5:$I$1004, 3) -> 48.5 | F39: =AVERAGEIFS(Master_Cleaned_Data!$W$5:$W$1004, Master_Cleaned_Data!$G$5:$G$1004, 10, Master_Cleaned_Data!$I$5:$I$1004, 4) -> 45.4 | G39: =AVERAGEIFS(Master_Cleaned_Data!$W$5:$W$1004, Master_Cleaned_Data!$G$5:$G$1004, 10, Master_Cleaned_Data!$I$5:$I$1004, 5) -> 52.333333 | H39: =AVERAGEIFS(Master_Cleaned_Data!$W$5:$W$1004, Master_Cleaned_Data!$G$5:$G$1004, 10, Master_Cleaned_Data!$I$5:$I$1004, 6) -> 54.571429 | I39: =AVERAGE(B39:H39) -> 52.905442
A40: 11:00 | B40: =AVERAGEIFS(Master_Cleaned_Data!$W$5:$W$1004, Master_Cleaned_Data!$G$5:$G$1004, 11, Master_Cleaned_Data!$I$5:$I$1004, 0) -> 85.571429 | C40: =AVERAGEIFS(Master_Cleaned_Data!$W$5:$W$1004, Master_Cleaned_Data!$G$5:$G$1004, 11, Master_Cleaned_Data!$I$5:$I$1004, 1) -> 47.666667 | D40: =AVERAGEIFS(Master_Cleaned_Data!$W$5:$W$1004, Master_Cleaned_Data!$G$5:$G$1004, 11, Master_Cleaned_Data!$I$5:$I$1004, 2) -> 50.8 | E40: =AVERAGEIFS(Master_Cleaned_Data!$W$5:$W$1004, Master_Cleaned_Data!$G$5:$G$1004, 11, Master_Cleaned_Data!$I$5:$I$1004, 3) -> 44.5 | F40: =AVERAGEIFS(Master_Cleaned_Data!$W$5:$W$1004, Master_Cleaned_Data!$G$5:$G$1004, 11, Master_Cleaned_Data!$I$5:$I$1004, 4) -> 54.6 | G40: =AVERAGEIFS(Master_Cleaned_Data!$W$5:$W$1004, Master_Cleaned_Data!$G$5:$G$1004, 11, Master_Cleaned_Data!$I$5:$I$1004, 5) -> 56.166667 | H40: =AVERAGEIFS(Master_Cleaned_Data!$W$5:$W$1004, Master_Cleaned_Data!$G$5:$G$1004, 11, Master_Cleaned_Data!$I$5:$I$1004, 6) -> 68.285714 | I40: =AVERAGE(B40:H40) -> 58.227211
A41: 12:00 | B41: =AVERAGEIFS(Master_Cleaned_Data!$W$5:$W$1004, Master_Cleaned_Data!$G$5:$G$1004, 12, Master_Cleaned_Data!$I$5:$I$1004, 0) -> 117 | C41: =AVERAGEIFS(Master_Cleaned_Data!$W$5:$W$1004, Master_Cleaned_Data!$G$5:$G$1004, 12, Master_Cleaned_Data!$I$5:$I$1004, 1) -> 65 | D41: =AVERAGEIFS(Master_Cleaned_Data!$W$5:$W$1004, Master_Cleaned_Data!$G$5:$G$1004, 12, Master_Cleaned_Data!$I$5:$I$1004, 2) -> 60.666667 | E41: =AVERAGEIFS(Master_Cleaned_Data!$W$5:$W$1004, Master_Cleaned_Data!$G$5:$G$1004, 12, Master_Cleaned_Data!$I$5:$I$1004, 3) -> 62.833333 | F41: =AVERAGEIFS(Master_Cleaned_Data!$W$5:$W$1004, Master_Cleaned_Data!$G$5:$G$1004, 12, Master_Cleaned_Data!$I$5:$I$1004, 4) -> 71.6 | G41: =AVERAGEIFS(Master_Cleaned_Data!$W$5:$W$1004, Master_Cleaned_Data!$G$5:$G$1004, 12, Master_Cleaned_Data!$I$5:$I$1004, 5) -> 64 | H41: =AVERAGEIFS(Master_Cleaned_Data!$W$5:$W$1004, Master_Cleaned_Data!$G$5:$G$1004, 12, Master_Cleaned_Data!$I$5:$I$1004, 6) -> 84.428571 | I41: =AVERAGE(B41:H41) -> 75.07551
A42: 13:00 | B42: =AVERAGEIFS(Master_Cleaned_Data!$W$5:$W$1004, Master_Cleaned_Data!$G$5:$G$1004, 13, Master_Cleaned_Data!$I$5:$I$1004, 0) -> 110.71429 | C42: =AVERAGEIFS(Master_Cleaned_Data!$W$5:$W$1004, Master_Cleaned_Data!$G$5:$G$1004, 13, Master_Cleaned_Data!$I$5:$I$1004, 1) -> 64.333333 | D42: =AVERAGEIFS(Master_Cleaned_Data!$W$5:$W$1004, Master_Cleaned_Data!$G$5:$G$1004, 13, Master_Cleaned_Data!$I$5:$I$1004, 2) -> 61 | E42: =AVERAGEIFS(Master_Cleaned_Data!$W$5:$W$1004, Master_Cleaned_Data!$G$5:$G$1004, 13, Master_Cleaned_Data!$I$5:$I$1004, 3) -> 64.833333 | F42: =AVERAGEIFS(Master_Cleaned_Data!$W$5:$W$1004, Master_Cleaned_Data!$G$5:$G$1004, 13, Master_Cleaned_Data!$I$5:$I$1004, 4) -> 72.2 | G42: =AVERAGEIFS(Master_Cleaned_Data!$W$5:$W$1004, Master_Cleaned_Data!$G$5:$G$1004, 13, Master_Cleaned_Data!$I$5:$I$1004, 5) -> 74.333333 | H42: =AVERAGEIFS(Master_Cleaned_Data!$W$5:$W$1004, Master_Cleaned_Data!$G$5:$G$1004, 13, Master_Cleaned_Data!$I$5:$I$1004, 6) -> 93.285714 | I42: =AVERAGE(B42:H42) -> 77.242857
A43: 14:00 | B43: =AVERAGEIFS(Master_Cleaned_Data!$W$5:$W$1004, Master_Cleaned_Data!$G$5:$G$1004, 14, Master_Cleaned_Data!$I$5:$I$1004, 0) -> 110.85714 | C43: =AVERAGEIFS(Master_Cleaned_Data!$W$5:$W$1004, Master_Cleaned_Data!$G$5:$G$1004, 14, Master_Cleaned_Data!$I$5:$I$1004, 1) -> 66.833333 | D43: =AVERAGEIFS(Master_Cleaned_Data!$W$5:$W$1004, Master_Cleaned_Data!$G$5:$G$1004, 14, Master_Cleaned_Data!$I$5:$I$1004, 2) -> 56.666667 | E43: =AVERAGEIFS(Master_Cleaned_Data!$W$5:$W$1004, Master_Cleaned_Data!$G$5:$G$1004, 14, Master_Cleaned_Data!$I$5:$I$1004, 3) -> 56.333333 | F43: =AVERAGEIFS(Master_Cleaned_Data!$W$5:$W$1004, Master_Cleaned_Data!$G$5:$G$1004, 14, Master_Cleaned_Data!$I$5:$I$1004, 4) -> 57.6 | G43: =AVERAGEIFS(Master_Cleaned_Data!$W$5:$W$1004, Master_Cleaned_Data!$G$5:$G$1004, 14, Master_Cleaned_Data!$I$5:$I$1004, 5) -> 64.833333 | H43: =AVERAGEIFS(Master_Cleaned_Data!$W$5:$W$1004, Master_Cleaned_Data!$G$5:$G$1004, 14, Master_Cleaned_Data!$I$5:$I$1004, 6) -> 95.428571 | I43: =AVERAGE(B43:H43) -> 72.65034
A44: 15:00 | B44: =AVERAGEIFS(Master_Cleaned_Data!$W$5:$W$1004, Master_Cleaned_Data!$G$5:$G$1004, 15, Master_Cleaned_Data!$I$5:$I$1004, 0) -> 114.14286 | C44: =AVERAGEIFS(Master_Cleaned_Data!$W$5:$W$1004, Master_Cleaned_Data!$G$5:$G$1004, 15, Master_Cleaned_Data!$I$5:$I$1004, 1) -> 60.166667 | D44: =AVERAGEIFS(Master_Cleaned_Data!$W$5:$W$1004, Master_Cleaned_Data!$G$5:$G$1004, 15, Master_Cleaned_Data!$I$5:$I$1004, 2) -> 55.666667 | E44: =AVERAGEIFS(Master_Cleaned_Data!$W$5:$W$1004, Master_Cleaned_Data!$G$5:$G$1004, 15, Master_Cleaned_Data!$I$5:$I$1004, 3) -> 62.666667 | F44: =AVERAGEIFS(Master_Cleaned_Data!$W$5:$W$1004, Master_Cleaned_Data!$G$5:$G$1004, 15, Master_Cleaned_Data!$I$5:$I$1004, 4) -> 60.4 | G44: =AVERAGEIFS(Master_Cleaned_Data!$W$5:$W$1004, Master_Cleaned_Data!$G$5:$G$1004, 15, Master_Cleaned_Data!$I$5:$I$1004, 5) -> 68.333333 | H44: =AVERAGEIFS(Master_Cleaned_Data!$W$5:$W$1004, Master_Cleaned_Data!$G$5:$G$1004, 15, Master_Cleaned_Data!$I$5:$I$1004, 6) -> 110 | I44: =AVERAGE(B44:H44) -> 75.910884
A45: 16:00 | B45: =AVERAGEIFS(Master_Cleaned_Data!$W$5:$W$1004, Master_Cleaned_Data!$G$5:$G$1004, 16, Master_Cleaned_Data!$I$5:$I$1004, 0) -> 106.57143 | C45: =AVERAGEIFS(Master_Cleaned_Data!$W$5:$W$1004, Master_Cleaned_Data!$G$5:$G$1004, 16, Master_Cleaned_Data!$I$5:$I$1004, 1) -> 83.666667 | D45: =AVERAGEIFS(Master_Cleaned_Data!$W$5:$W$1004, Master_Cleaned_Data!$G$5:$G$1004, 16, Master_Cleaned_Data!$I$5:$I$1004, 2) -> 80.5 | E45: =AVERAGEIFS(Master_Cleaned_Data!$W$5:$W$1004, Master_Cleaned_Data!$G$5:$G$1004, 16, Master_Cleaned_Data!$I$5:$I$1004, 3) -> 79.833333 | F45: =AVERAGEIFS(Master_Cleaned_Data!$W$5:$W$1004, Master_Cleaned_Data!$G$5:$G$1004, 16, Master_Cleaned_Data!$I$5:$I$1004, 4) -> 72.833333 | G45: =AVERAGEIFS(Master_Cleaned_Data!$W$5:$W$1004, Master_Cleaned_Data!$G$5:$G$1004, 16, Master_Cleaned_Data!$I$5:$I$1004, 5) -> 96.333333 | H45: =AVERAGEIFS(Master_Cleaned_Data!$W$5:$W$1004, Master_Cleaned_Data!$G$5:$G$1004, 16, Master_Cleaned_Data!$I$5:$I$1004, 6) -> 100.42857 | I45: =AVERAGE(B45:H45) -> 88.595238
A46: 17:00 | B46: =AVERAGEIFS(Master_Cleaned_Data!$W$5:$W$1004, Master_Cleaned_Data!$G$5:$G$1004, 17, Master_Cleaned_Data!$I$5:$I$1004, 0) -> 87.142857 | C46: =AVERAGEIFS(Master_Cleaned_Data!$W$5:$W$1004, Master_Cleaned_Data!$G$5:$G$1004, 17, Master_Cleaned_Data!$I$5:$I$1004, 1) -> 161.16667 | D46: =AVERAGEIFS(Master_Cleaned_Data!$W$5:$W$1004, Master_Cleaned_Data!$G$5:$G$1004, 17, Master_Cleaned_Data!$I$5:$I$1004, 2) -> 174.5 | E46: =AVERAGEIFS(Master_Cleaned_Data!$W$5:$W$1004, Master_Cleaned_Data!$G$5:$G$1004, 17, Master_Cleaned_Data!$I$5:$I$1004, 3) -> 151.33333 | F46: =AVERAGEIFS(Master_Cleaned_Data!$W$5:$W$1004, Master_Cleaned_Data!$G$5:$G$1004, 17, Master_Cleaned_Data!$I$5:$I$1004, 4) -> 162.16667 | G46: =AVERAGEIFS(Master_Cleaned_Data!$W$5:$W$1004, Master_Cleaned_Data!$G$5:$G$1004, 17, Master_Cleaned_Data!$I$5:$I$1004, 5) -> 178.66667 | H46: =AVERAGEIFS(Master_Cleaned_Data!$W$5:$W$1004, Master_Cleaned_Data!$G$5:$G$1004, 17, Master_Cleaned_Data!$I$5:$I$1004, 6) -> 84.571429 | I46: =AVERAGE(B46:H46) -> 142.79252
A47: 18:00 | B47: =AVERAGEIFS(Master_Cleaned_Data!$W$5:$W$1004, Master_Cleaned_Data!$G$5:$G$1004, 18, Master_Cleaned_Data!$I$5:$I$1004, 0) -> 65 | C47: =AVERAGEIFS(Master_Cleaned_Data!$W$5:$W$1004, Master_Cleaned_Data!$G$5:$G$1004, 18, Master_Cleaned_Data!$I$5:$I$1004, 1) -> 148 | D47: =AVERAGEIFS(Master_Cleaned_Data!$W$5:$W$1004, Master_Cleaned_Data!$G$5:$G$1004, 18, Master_Cleaned_Data!$I$5:$I$1004, 2) -> 159.16667 | E47: =AVERAGEIFS(Master_Cleaned_Data!$W$5:$W$1004, Master_Cleaned_Data!$G$5:$G$1004, 18, Master_Cleaned_Data!$I$5:$I$1004, 3) -> 163.8 | F47: =AVERAGEIFS(Master_Cleaned_Data!$W$5:$W$1004, Master_Cleaned_Data!$G$5:$G$1004, 18, Master_Cleaned_Data!$I$5:$I$1004, 4) -> 150.5 | G47: =AVERAGEIFS(Master_Cleaned_Data!$W$5:$W$1004, Master_Cleaned_Data!$G$5:$G$1004, 18, Master_Cleaned_Data!$I$5:$I$1004, 5) -> 136.66667 | H47: =AVERAGEIFS(Master_Cleaned_Data!$W$5:$W$1004, Master_Cleaned_Data!$G$5:$G$1004, 18, Master_Cleaned_Data!$I$5:$I$1004, 6) -> 63.285714 | I47: =AVERAGE(B47:H47) -> 126.63129
A48: 19:00 | B48: =AVERAGEIFS(Master_Cleaned_Data!$W$5:$W$1004, Master_Cleaned_Data!$G$5:$G$1004, 19, Master_Cleaned_Data!$I$5:$I$1004, 0) -> 45.571429 | C48: =AVERAGEIFS(Master_Cleaned_Data!$W$5:$W$1004, Master_Cleaned_Data!$G$5:$G$1004, 19, Master_Cleaned_Data!$I$5:$I$1004, 1) -> 101.66667 | D48: =AVERAGEIFS(Master_Cleaned_Data!$W$5:$W$1004, Master_Cleaned_Data!$G$5:$G$1004, 19, Master_Cleaned_Data!$I$5:$I$1004, 2) -> 102.83333 | E48: =AVERAGEIFS(Master_Cleaned_Data!$W$5:$W$1004, Master_Cleaned_Data!$G$5:$G$1004, 19, Master_Cleaned_Data!$I$5:$I$1004, 3) -> 101.2 | F48: =AVERAGEIFS(Master_Cleaned_Data!$W$5:$W$1004, Master_Cleaned_Data!$G$5:$G$1004, 19, Master_Cleaned_Data!$I$5:$I$1004, 4) -> 108.33333 | G48: =AVERAGEIFS(Master_Cleaned_Data!$W$5:$W$1004, Master_Cleaned_Data!$G$5:$G$1004, 19, Master_Cleaned_Data!$I$5:$I$1004, 5) -> 96 | H48: =AVERAGEIFS(Master_Cleaned_Data!$W$5:$W$1004, Master_Cleaned_Data!$G$5:$G$1004, 19, Master_Cleaned_Data!$I$5:$I$1004, 6) -> 54.714286 | I48: =AVERAGE(B48:H48) -> 87.188435
A49: 20:00 | B49: =AVERAGEIFS(Master_Cleaned_Data!$W$5:$W$1004, Master_Cleaned_Data!$G$5:$G$1004, 20, Master_Cleaned_Data!$I$5:$I$1004, 0) -> 36.857143 | C49: =AVERAGEIFS(Master_Cleaned_Data!$W$5:$W$1004, Master_Cleaned_Data!$G$5:$G$1004, 20, Master_Cleaned_Data!$I$5:$I$1004, 1) -> 67.666667 | D49: =AVERAGEIFS(Master_Cleaned_Data!$W$5:$W$1004, Master_Cleaned_Data!$G$5:$G$1004, 20, Master_Cleaned_Data!$I$5:$I$1004, 2) -> 69.666667 | E49: =AVERAGEIFS(Master_Cleaned_Data!$W$5:$W$1004, Master_Cleaned_Data!$G$5:$G$1004, 20, Master_Cleaned_Data!$I$5:$I$1004, 3) -> 76 | F49: =AVERAGEIFS(Master_Cleaned_Data!$W$5:$W$1004, Master_Cleaned_Data!$G$5:$G$1004, 20, Master_Cleaned_Data!$I$5:$I$1004, 4) -> 87.333333 | G49: =AVERAGEIFS(Master_Cleaned_Data!$W$5:$W$1004, Master_Cleaned_Data!$G$5:$G$1004, 20, Master_Cleaned_Data!$I$5:$I$1004, 5) -> 61.333333 | H49: =AVERAGEIFS(Master_Cleaned_Data!$W$5:$W$1004, Master_Cleaned_Data!$G$5:$G$1004, 20, Master_Cleaned_Data!$I$5:$I$1004, 6) -> 43.142857 | I49: =AVERAGE(B49:H49) -> 63.142857
A50: 21:00 | B50: =AVERAGEIFS(Master_Cleaned_Data!$W$5:$W$1004, Master_Cleaned_Data!$G$5:$G$1004, 21, Master_Cleaned_Data!$I$5:$I$1004, 0) -> 30 | C50: =AVERAGEIFS(Master_Cleaned_Data!$W$5:$W$1004, Master_Cleaned_Data!$G$5:$G$1004, 21, Master_Cleaned_Data!$I$5:$I$1004, 1) -> 51.666667 | D50: =AVERAGEIFS(Master_Cleaned_Data!$W$5:$W$1004, Master_Cleaned_Data!$G$5:$G$1004, 21, Master_Cleaned_Data!$I$5:$I$1004, 2) -> 45.333333 | E50: =AVERAGEIFS(Master_Cleaned_Data!$W$5:$W$1004, Master_Cleaned_Data!$G$5:$G$1004, 21, Master_Cleaned_Data!$I$5:$I$1004, 3) -> 61 | F50: =AVERAGEIFS(Master_Cleaned_Data!$W$5:$W$1004, Master_Cleaned_Data!$G$5:$G$1004, 21, Master_Cleaned_Data!$I$5:$I$1004, 4) -> 51.5 | G50: =AVERAGEIFS(Master_Cleaned_Data!$W$5:$W$1004, Master_Cleaned_Data!$G$5:$G$1004, 21, Master_Cleaned_Data!$I$5:$I$1004, 5) -> 46.666667 | H50: =AVERAGEIFS(Master_Cleaned_Data!$W$5:$W$1004, Master_Cleaned_Data!$G$5:$G$1004, 21, Master_Cleaned_Data!$I$5:$I$1004, 6) -> 44.285714 | I50: =AVERAGE(B50:H50) -> 47.207483
A51: 22:00 | B51: =AVERAGEIFS(Master_Cleaned_Data!$W$5:$W$1004, Master_Cleaned_Data!$G$5:$G$1004, 22, Master_Cleaned_Data!$I$5:$I$1004, 0) -> 27.428571 | C51: =AVERAGEIFS(Master_Cleaned_Data!$W$5:$W$1004, Master_Cleaned_Data!$G$5:$G$1004, 22, Master_Cleaned_Data!$I$5:$I$1004, 1) -> 27.166667 | D51: =AVERAGEIFS(Master_Cleaned_Data!$W$5:$W$1004, Master_Cleaned_Data!$G$5:$G$1004, 22, Master_Cleaned_Data!$I$5:$I$1004, 2) -> 35.833333 | E51: =AVERAGEIFS(Master_Cleaned_Data!$W$5:$W$1004, Master_Cleaned_Data!$G$5:$G$1004, 22, Master_Cleaned_Data!$I$5:$I$1004, 3) -> 44 | F51: =AVERAGEIFS(Master_Cleaned_Data!$W$5:$W$1004, Master_Cleaned_Data!$G$5:$G$1004, 22, Master_Cleaned_Data!$I$5:$I$1004, 4) -> 42.833333 | G51: =AVERAGEIFS(Master_Cleaned_Data!$W$5:$W$1004, Master_Cleaned_Data!$G$5:$G$1004, 22, Master_Cleaned_Data!$I$5:$I$1004, 5) -> 36.833333 | H51: =AVERAGEIFS(Master_Cleaned_Data!$W$5:$W$1004, Master_Cleaned_Data!$G$5:$G$1004, 22, Master_Cleaned_Data!$I$5:$I$1004, 6) -> 34.285714 | I51: =AVERAGE(B51:H51) -> 35.482993
A52: 23:00 | B52: =AVERAGEIFS(Master_Cleaned_Data!$W$5:$W$1004, Master_Cleaned_Data!$G$5:$G$1004, 23, Master_Cleaned_Data!$I$5:$I$1004, 0) -> 19.142857 | C52: =AVERAGEIFS(Master_Cleaned_Data!$W$5:$W$1004, Master_Cleaned_Data!$G$5:$G$1004, 23, Master_Cleaned_Data!$I$5:$I$1004, 1) -> 16.666667 | D52: =AVERAGEIFS(Master_Cleaned_Data!$W$5:$W$1004, Master_Cleaned_Data!$G$5:$G$1004, 23, Master_Cleaned_Data!$I$5:$I$1004, 2) -> 19.666667 | E52: =AVERAGEIFS(Master_Cleaned_Data!$W$5:$W$1004, Master_Cleaned_Data!$G$5:$G$1004, 23, Master_Cleaned_Data!$I$5:$I$1004, 3) -> 27.2 | F52: =AVERAGEIFS(Master_Cleaned_Data!$W$5:$W$1004, Master_Cleaned_Data!$G$5:$G$1004, 23, Master_Cleaned_Data!$I$5:$I$1004, 4) -> 26.166667 | G52: =AVERAGEIFS(Master_Cleaned_Data!$W$5:$W$1004, Master_Cleaned_Data!$G$5:$G$1004, 23, Master_Cleaned_Data!$I$5:$I$1004, 5) -> 29.333333 | H52: =AVERAGEIFS(Master_Cleaned_Data!$W$5:$W$1004, Master_Cleaned_Data!$G$5:$G$1004, 23, Master_Cleaned_Data!$I$5:$I$1004, 6) -> 37.428571 | I52: =AVERAGE(B52:H52) -> 25.086395
A53: Day Average | B53: =AVERAGE(B29:B52) -> 48.383929 | C53: =AVERAGE(C29:C52) -> 57.880754 | D53: =AVERAGE(D29:D52) -> 62.25 | E53: =AVERAGE(E29:E52) -> 59.258333 | F53: =AVERAGE(F29:F52) -> 64.678472 | G53: =AVERAGE(G29:G52) -> 63.201389 | H53: =AVERAGE(H29:H52) -> 46.159524 | I53: =AVERAGE(I29:I52) -> 57.401772
A55: INTERACTIVE SLICERS & OPERATIONAL FILTER CONTROLS (EXCEL BI SUITE)
A56: • Slicer 1: [Day Type Filter] - Connected to Final_Data_Set / Master table. Allows 1-click toggling between Weekday, Weekend, and Holiday to analyze commuter vs recreational demand patterns.
A57: • Slicer 2: [Weather Situation Filter] - Filters between Clear, Mist, Rain/Snow, and Heavy Storms to evaluate fleet weather vulnerability and rain-penalty thresholds.
A58: • Slicer 3: [Month Filter] - Filters between January and February to analyze seasonal expansion, weekly compounding ridership growth (+38.6%), and operational scaling.
A59: • Operational Tip: In Excel, click on any Pivot Table or the Master Data table and choose Insert > Slicer to activate dynamic floating visual buttons.

Sheet Dataset_1_Raw
A1: instant | B1: dteday | C1: season | D1: yr | E1: mnth | F1: hr | G1: holiday | H1: weekday | I1: weathersit | J1: temp
A2: 1 | B2: 2011-01-01 | C2: 1 | D2: 0 | E2: 1 | F2: 0 | G2: =FALSE() -> FALSE | H2: 6 | I2: 1 | J2: 0.24
A3: 2 | B3: 2011-01-01 | C3: 1 | D3: 0 | E3: 1 | F3: 1 | G3: =FALSE() -> FALSE | H3: 6 | I3: 1 | J3: 0.22
A4: 3 | B4: 2011-01-01 | C4: 1 | D4: 0 | E4: 1 | F4: 2 | G4: =FALSE() -> FALSE | H4: 6 | I4: 1 | J4: 0.22
A5: 4 | B5: 2011-01-01 | C5: 1 | D5: 0 | E5: 1 | F5: 3 | G5: =FALSE() -> FALSE | H5: 6 | I5: 1 | J5: 0.24
A6: 5 | B6: 2011-01-01 | C6: 1 | D6: 0 | E6: 1 | F6: 4 | G6: =FALSE() -> FALSE | H6: 6 | I6: 1 | J6: 0.24
A7: 6 | B7: 2011-01-01 | C7: 1 | D7: 0 | E7: 1 | F7: 5 | G7: =FALSE() -> FALSE | H7: 6 | I7: 2 | J7: 0.24
A8: 7 | B8: 2011-01-01 | C8: 1 | D8: 0 | E8: 1 | F8: 6 | G8: =FALSE() -> FALSE | H8: 6 | I8: 1 | J8: 0.22
A9: 8 | B9: 2011-01-01 | C9: 1 | D9: 0 | E9: 1 | F9: 7 | G9: =FALSE() -> FALSE | H9: 6 | I9: 1 | J9: 0.2
A10: 9 | B10: 2011-01-01 | C10: 1 | D10: 0 | E10: 1 | F10: 8 | G10: =FALSE() -> FALSE | H10: 6 | I10: 1 | J10: 0.24
A11: 10 | B11: 2011-01-01 | C11: 1 | D11: 0 | E11: 1 | F11: 9 | G11: =FALSE() -> FALSE | H11: 6 | I11: 1 | J11: 0.32
A12: 11 | B12: 2011-01-01 | C12: 1 | D12: 0 | E12: 1 | F12: 10 | G12: =FALSE() -> FALSE | H12: 6 | I12: 1 | J12: 0.38
A13: 12 | B13: 2011-01-01 | C13: 1 | D13: 0 | E13: 1 | F13: 11 | G13: =FALSE() -> FALSE | H13: 6 | I13: 1 | J13: 0.36
... A373: 372 | B373: 2011-01-16 | C373: 1 | D373: 0 | E373: 1 | F373: 23 | G373: =FALSE() -> FALSE | H373: 0 | I373: 2 | J373: 0.2
A374: 373 | B374: 2011-01-17 | C374: 1 | D374: 0 | E374: 1 | F374: 0 | G374: =TRUE() -> TRUE | H374: 1 | I374: 2 | J374: 0.2
A375: 374 | B375: 2011-01-17 | C375: 1 | D375: 0 | E375: 1 | F375: 1 | G375: =TRUE() -> TRUE | H375: 1 | I375: 2 | J375: 0.2
A376: 375 | B376: 2011-01-17 | C376: 1 | D376: 0 | E376: 1 | F376: 2 | G376: =TRUE() -> TRUE | H376: 1 | I376: 2 | J376: 0.18
A377: 376 | B377: 2011-01-17 | C377: 1 | D377: 0 | E377: 1 | F377: 3 | G377: =TRUE() -> TRUE | H377: 1 | I377: 2 | J377: 0.18
A378: 377 | B378: 2011-01-17 | C378: 1 | D378: 0 | E378: 1 | F378: 4 | G378: =TRUE() -> TRUE | H378: 1 | I378: 2 | J378: 0.18
A379: 378 | B379: 2011-01-17 | C379: 1 | D379: 0 | E379: 1 | F379: 5 | G379: =TRUE() -> TRUE | H379: 1 | I379: 2 | J379: 0.18
A380: 379 | B380: 2011-01-17 | C380: 1 | D380: 0 | E380: 1 | F380: 6 | G380: =TRUE() -> TRUE | H380: 1 | I380: 2 | J380: 0.18
A381: 380 | B381: 2011-01-17 | C381: 1 | D381: 0 | E381: 1 | F381: 7 | G381: =TRUE() -> TRUE | H381: 1 | I381: 2 | J381: 0.16
A382: 381 | B382: 2011-01-17 | C382: 1 | D382: 0 | E382: 1 | F382: 8 | G382: =TRUE() -> TRUE | H382: 1 | I382: 2 | J382: 0.16
A383: 382 | B383: 2011-01-17 | C383: 1 | D383: 0 | E383: 1 | F383: 9 | G383: =TRUE() -> TRUE | H383: 1 | I383: 2 | J383: 0.16
A384: 383 | B384: 2011-01-17 | C384: 1 | D384: 0 | E384: 1 | F384: 10 | G384: =TRUE() -> TRUE | H384: 1 | I384: 2 | J384: 0.16
A385: 384 | B385: 2011-01-17 | C385: 1 | D385: 0 | E385: 1 | F385: 11 | G385: =TRUE() -> TRUE | H385: 1 | I385: 2 | J385: 0.16
... A397: 396 | B397: 2011-01-17 | C397: 1 | D397: 0 | E397: 1 | F397: 23 | G397: =TRUE() -> TRUE | H397: 1 | I397: 3 | J397: 0.16
A398: 397 | B398: 2011-01-18 | C398: 1 | D398: 0 | E398: 1 | F398: 12 | G398: =FALSE() -> FALSE | H398: 2 | I398: 2 | J398: 0.2
A399: 398 | B399: 2011-01-18 | C399: 1 | D399: 0 | E399: 1 | F399: 13 | G399: =FALSE() -> FALSE | H399: 2 | I399: 2 | J399: 0.2
A400: 399 | B400: 2011-01-18 | C400: 1 | D400: 0 | E400: 1 | F400: 14 | G400: =FALSE() -> FALSE | H400: 2 | I400: 2 | J400: 0.22
A401: 400 | B401: 2011-01-18 | C401: 1 | D401: 0 | E401: 1 | F401: 15 | G401: =FALSE() -> FALSE | H401: 2 | I401: 2 | J401: 0.22
A402: 401 | B402: 2011-01-18 | C402: 1 | D402: 0 | E402: 1 | F402: 16 | G402: =FALSE() -> FALSE | H402: 2 | I402: 2 | J402: 0.22
A403: 402 | B403: 2011-01-18 | C403: 1 | D403: 0 | E403: 1 | F403: 17 | G403: =FALSE() -> FALSE | H403: 2 | I403: 2 | J403: 0.22
A404: 403 | B404: 2011-01-18 | C404: 1 | D404: 0 | E404: 1 | F404: 18 | G404: =FALSE() -> FALSE | H404: 2 | I404: 2 | J404: 0.22
A405: 404 | B405: 2011-01-18 | C405: 1 | D405: 0 | E405: 1 | F405: 19 | G405: =FALSE() -> FALSE | H405: 2 | I405: 2 | J405: 0.22
A406: 405 | B406: 2011-01-18 | C406: 1 | D406: 0 | E406: 1 | F406: 20 | G406: =FALSE() -> FALSE | H406: 2 | I406: 2 | J406: 0.22
A407: 406 | B407: 2011-01-18 | C407: 1 | D407: 0 | E407: 1 | F407: 21 | G407: =FALSE() -> FALSE | H407: 2 | I407: 2 | J407: 0.22
A408: 407 | B408: 2011-01-18 | C408: 1 | D408: 0 | E408: 1 | F408: 22 | G408: =FALSE() -> FALSE | H408: 2 | I408: 2 | J408: 0.22
A409: 408 | B409: 2011-01-18 | C409: 1 | D409: 0 | E409: 1 | F409: 23 | G409: =FALSE() -> FALSE | H409: 2 | I409: 2 | J409: 0.22
... A611: 610 | B611: 2011-01-28 | C611: 1 | D611: 0 | E611: 1 | F611: 15 | G611: =FALSE() -> FALSE | H611: 5 | I611: 2 | J611: 0.2

Sheet Dataset_2_Raw
A1: Unnamed: 0 | B1: instant | C1: atemp | D1: hum | E1: windspeed | F1: casual | G1: registered | H1: cnt
A2: 0 | B2: 1 | C2: 0.2879 | D2: 0.81 | E2: 0 | F2: 3 | G2: 13 | H2: 16
A3: 1 | B3: 2 | C3: 0.2727 | D3: 0.8 | E3: 0 | F3: 8 | G3: 32 | H3: 40
A4: 2 | B4: 3 | C4: 0.2727 | D4: 0.8 | E4: 0 | F4: 5 | G4: 27 | H4: 32
A5: 3 | B5: 4 | C5: 0.2879 | D5: 0.75 | E5: 0 | F5: 3 | G5: 10 | H5: 13
A6: 4 | B6: 5 | C6: 0.2879 | D6: 0.75 | E6: 0 | F6: 0 | G6: 1 | H6: 1
A7: 5 | B7: 6 | C7: 0.2576 | D7: 0.75 | E7: 0.0896 | F7: 0 | G7: 1 | H7: 1
A8: 6 | B8: 7 | C8: 0.2727 | D8: 0.8 | E8: 0 | F8: 2 | G8: 0 | H8: 2
A9: 7 | B9: 8 | C9: 0.2576 | D9: 0.86 | E9: 0 | F9: 1 | G9: 2 | H9: 3
A10: 8 | B10: 9 | D10: 0.75 | E10: 0 | F10: 1 | G10: 7 | H10: 8
A11: 9 | B11: 10 | C11: 0.3485 | D11: 0.76 | E11: 0 | F11: 8 | G11: 6 | H11: 14
A12: 10 | B12: 11 | C12: 0.3939 | D12: 0.76 | E12: 0.2537 | F12: 12 | G12: 24 | H12: 36
A13: 11 | B13: 12 | C13: 0.3333 | D13: 0.81 | E13: 0.2836 | F13: 26 | G13: 30 | H13: 56
A14: 12 | B14: 13 | C14: 0.4242 | D14: 0.77 | E14: 0.2836 | F14: 29 | G14: 55 | H14: 84
A15: 13 | B15: 14 | C15: 0.4545 | D15: 0.72 | E15: 0.2985 | F15: 47 | G15: 47 | H15: 94
A16: 14 | B16: 15 | C16: 0.4545 | D16: 0.72 | E16: 0.2836 | F16: 35 | G16: 71 | H16: 106
A17: 15 | B17: 16 | C17: 0.4394 | D17: 0.77 | E17: 0.2985 | F17: 40 | G17: 70 | H17: 110
A18: 16 | B18: 17 | C18: 0.4242 | D18: 0.82 | E18: 0.2985 | F18: 41 | G18: 52 | H18: 93
A19: 17 | B19: 18 | D19: 0.82 | E19: 0.2836 | F19: 15 | G19: 52 | H19: 67
A20: 18 | B20: 19 | C20: 0.4242 | D20: 0.88 | E20: 0.2537 | F20: 9 | G20: 26 | H20: 35
A21: 19 | B21: 20 | C21: 0.4242 | D21: 0.88 | E21: 0.2537 | F21: 6 | G21: 31 | H21: 37
A22: 20 | B22: 21 | C22: 0.4091 | D22: 0.87 | E22: 0.2537 | F22: 11 | G22: 25 | H22: 36
A23: 21 | B23: 22 | C23: 0.4091 | D23: 0.87 | E23: 0.194 | F23: 3 | G23: 31 | H23: 34
A24: 22 | B24: 23 | C24: 0.4091 | D24: 0.94 | E24: 0.2239 | F24: 11 | G24: 17 | H24: 28
A25: 23 | B25: 24 | D25: 0.88 | E25: 0.2985 | F25: 15 | G25: 24 | H25: 39
A26: 24 | B26: 25 | C26: 0.4545 | D26: 0.88 | E26: 0.2985 | F26: 4 | G26: 13 | H26: 17
A27: 25 | B27: 26 | C27: 0.4394 | D27: 0.94 | E27: 0.2537 | F27: 1 | G27: 16 | H27: 17
A28: 26 | B28: 27 | C28: 0.4242 | D28: 1 | E28: 0.2836 | F28: 1 | G28: 8 | H28: 9
A29: 27 | B29: 28 | C29: 0.4545 | D29: 0.94 | E29: 0.194 | F29: 2 | G29: 4 | H29: 6
A30: 28 | B30: 29 | D30: 0.94 | E30: 0.194 | F30: 2 | G30: 1 | H30: 3
A31: 29 | B31: 30 | C31: 0.4242 | D31: 0.77 | E31: 0.2985 | F31: 0 | G31: 2 | H31: 2
A32: 30 | B32: 31 | C32: 0.4091 | D32: 0.76 | E32: 0.194 | F32: 0 | G32: 1 | H32: 1
A33: 31 | B33: 32 | C33: 0.4091 | D33: 0.71 | E33: 0.2239 | F33: 0 | G33: 8 | H33: 8
A34: 32 | B34: 33 | D34: 0.76 | E34: 0.2239 | F34: 1 | G34: 19 | H34: 20
A35: 33 | B35: 34 | C35: 0.3485 | D35: 0.81 | E35: 0.2239 | F35: 7 | G35: 46 | H35: 53
A36: 34 | B36: 35 | C36: 0.3333 | D36: 0.71 | E36: 0.2537 | F36: 16 | G36: 54 | H36: 70
A37: 35 | B37: 36 | C37: 0.3333 | D37: 0.66 | E37: 0.2985 | F37: 20 | G37: 73 | H37: 93
A38: 36 | B38: 37 | C38: 0.3485 | D38: 0.66 | E38: 0.1343 | F38: 11 | G38: 64 | H38: 75
A39: 37 | B39: 38 | D39: 0.76 | E39: 0.194 | F39: 4 | G39: 55 | H39: 59
A40: 38 | B40: 39 | C40: 0.3333 | D40: 0.81 | E40: 0.1642 | F40: 19 | G40: 55 | H40: 74
...

Sheet Dataset_3_Raw
A1: instant | B1: dteday | C1: season | D1: yr | E1: mnth | F1: hr | G1: holiday | H1: weekday | I1: weathersit | J1: temp | K1: atemp | L1: hum | M1: windspeed | N1: casual | O1: registered | P1: cnt
A2: 620 | B2: 2011-01-29 | C2: 1 | D2: 0 | E2: 1 | F2: 1 | G2: =FALSE() -> FALSE | H2: 6 | I2: 1 | J2: 0.22 | K2: 0.2273 | L2: 0.64 | M2: 0.194 | N2: 0 | O2: 20 | P2: 20
A3: 621 | B3: 2011-01-29 | C3: 1 | D3: 0 | E3: 1 | F3: 2 | G3: =FALSE() -> FALSE | H3: 6 | I3: 1 | J3: 0.22 | K3: 0.2273 | L3: 0.64 | M3: 0.1642 | N3: 0 | O3: 15 | P3: 15
A4: 622 | B4: 2011-01-29 | C4: 1 | D4: 0 | E4: 1 | F4: 3 | G4: =FALSE() -> FALSE | H4: 6 | I4: 1 | J4: 0.2 | K4: 0.2121 | L4: 0.64 | M4: 0.1343 | N4: 3 | O4: 5 | P4: 8
A5: 623 | B5: 2011-01-29 | C5: 1 | D5: 0 | E5: 1 | F5: 4 | G5: =FALSE() -> FALSE | H5: 6 | I5: 1 | J5: 0.16 | K5: 0.1818 | L5: 0.69 | M5: 0.1045 | N5: 1 | O5: 2 | P5: 3
A6: 624 | B6: 2011-01-29 | C6: 1 | D6: 0 | E6: 1 | F6: 6 | G6: =FALSE() -> FALSE | H6: 6 | I6: 1 | J6: 0.16 | K6: 0.1818 | L6: 0.64 | M6: 0.1343 | N6: 0 | O6: 2 | P6: 2
A7: 625 | B7: 2011-01-29 | C7: 1 | D7: 0 | E7: 1 | F7: 7 | G7: =FALSE() -> FALSE | H7: 6 | I7: 1 | J7: 0.16 | K7: 0.1818 | L7: 0.59 | M7: 0.1045 | N7: 1 | O7: 4 | P7: 5
A8: 626 | B8: 2011-01-29 | C8: 1 | D8: 0 | E8: 1 | F8: 8 | G8: =FALSE() -> FALSE | H8: 6 | I8: 1 | J8: 0.18 | K8: 0.197 | L8: 0.55 | M8: 0.1642 | N8: 3 | O8: 31 | P8: 34
A9: 627 | B9: 2011-01-29 | C9: 1 | D9: 0 | E9: 1 | F9: 9 | G9: =FALSE() -> FALSE | H9: 6 | I9: 1 | J9: 0.18 | K9: 0.2121 | L9: 0.59 | M9: 0.0896 | N9: 0 | O9: 34 | P9: 34
A10: 628 | B10: 2011-01-29 | C10: 1 | D10: 0 | E10: 1 | F10: 10 | G10: =FALSE() -> FALSE | H10: 6 | I10: 2 | J10: 0.18 | K10: 0.2121 | L10: 0.64 | M10: 0.1045 | N10: 4 | O10: 51 | P10: 55
A11: 629 | B11: 2011-01-29 | C11: 1 | D11: 0 | E11: 1 | F11: 11 | G11: =FALSE() -> FALSE | H11: 6 | I11: 2 | J11: 0.18 | K11: 0.197 | L11: 0.64 | M11: 0.1343 | N11: 4 | O11: 60 | P11: 64
A12: 630 | B12: 2011-01-29 | C12: 1 | D12: 0 | E12: 1 | F12: 12 | G12: =FALSE() -> FALSE | H12: 6 | I12: 2 | J12: 0.2 | K12: 0.197 | L12: 0.59 | M12: 0.194 | N12: 12 | O12: 66 | P12: 78
A13: 631 | B13: 2011-01-29 | C13: 1 | D13: 0 | E13: 1 | F13: 13 | G13: =FALSE() -> FALSE | H13: 6 | I13: 2 | J13: 0.22 | K13: 0.2273 | L13: 0.55 | M13: 0.1642 | N13: 9 | O13: 56 | P13: 65
... A391: 619 | B391: 2011-01-29 | C391: 1 | D391: 0 | E391: 1 | F391: 0 | G391: =FALSE() -> FALSE | H391: 6 | I391: 1 | J391: 0.22 | K391: 0.197 | L391: 0.64 | M391: 0.3582 | N391: 2 | O391: 26 | P391: 28

Sheet Lookups_Metadata
A1: NEXTHIKES IT SOLUTIONS | SYSTEM LOOKUP TABLES & DATA DICTIONARY
A3: Season Code | B3: Season Name | D3: Weekday Code | E3: Weekday Name | G3: Weather Code | H3: Weather Description | J3: Demand Level | K3: Threshold Rule
A4: 1 | B4: Spring | D4: 0 | E4: Sunday | G4: 1 | H4: Clear / Few Clouds | J4: Low Demand | K4: < 50 rides/hr
A5: 2 | B5: Summer | D5: 1 | E5: Monday | G5: 2 | H5: Mist / Cloudy | J5: Moderate Demand | K5: 50 to 149 rides/hr
A6: 3 | B6: Fall | D6: 2 | E6: Tuesday | G6: 3 | H6: Light Snow / Light Rain | J6: High Demand | K6: >= 150 rides/hr
A7: 4 | B7: Winter | D7: 3 | E7: Wednesday | G7: 4 | H7: Heavy Rain / Ice Pellets | J7: Peak Commute | K7: Weekdays 07:00-09:00 & 17:00-19:00
D8: 4 | E8: Thursday
D9: 5 | E9: Friday
D10: 6 | E10: Saturday
A13: DATA DICTIONARY & FIELD SPECIFICATIONS
A14: Field Name | B14: Source Tab | C14: Type | D14: Excel Transformation / Formula Logic | E14: Business Definition & Analytic Utility
A15: instant | B15: Dataset 1 & 3 | C15: Integer | D15: Primary Key identifier (1 to 1000) | E15: Sequential record number tracking chronological hourly progression.
A16: dteday | B16: Dataset 1 & 3 | C16: Date | D16: Format YYYY-MM-DD | E16: Observation date spanning 2011-01-01 through 2011-02-14.
A17: season | B17: Dataset 1 & 3 | C17: Integer | D17: 1=Spring, 2=Summer, 3=Fall, 4=Winter | E17: Seasonal indicator (all rows in Winter/Spring code 1).
A18: Season_Name | B18: Derived | C18: Text | D18: VLOOKUP(C5, Lookups_Metadata!$A$4:$B$7, 2, FALSE) | E18: Decoded textual name of season.
A19: yr | B19: Dataset 1 & 3 | C19: Integer | D19: 0=2011, 1=2012 | E19: Year indicator code.
A20: mnth | B20: Dataset 1 & 3 | C20: Integer | D20: 1 to 12 | E20: Calendar month of observation (1=January, 2=February).
A21: hr | B21: Dataset 1 & 3 | C21: Integer | D21: 0 to 23 | E21: Hour of day in 24-hour wall-clock notation.
A22: holiday | B22: Dataset 1 & 3 | C22: Boolean | D22: TRUE / FALSE | E22: Whether the day was an official public holiday (e.g. MLK Day).
A23: weekday | B23: Dataset 1 & 3 | C23: Integer | D23: 0=Sunday to 6=Saturday | E23: Day-of-week index.
A24: Weekday_Name | B24: Derived | C24: Text | D24: INDEX(Lookups_Metadata!$E$4:$E$10, MATCH(I5, Lookups_Metadata!$D$4:$D$10, 0)) | E24: Decoded human-readable weekday name via INDEX-MATCH.
A25: Day_Type | B25: Derived | C25: Text | D25: IF(H5=TRUE, "Holiday", IF(OR(I5=0, I5=6), "Weekend", "Weekday")) | E25: Operational categorization: Weekday, Weekend, or Holiday.
... A46: Date_Right_Day | B46: Derived | C46: Text | D46: RIGHT(TEXT(B5, "YYYY-MM-DD"), 2) | E46: Day of month extraction via RIGHT text function.

Sheet Master_Cleaned_Data
A1: NEXTHIKES IT SOLUTIONS | MASTER CONSOLIDATED & CLEANED BIKE DEMAND DATASET
A2: Hourly Records 1 to 1,000 | Merged Keys: instant, dteday, hr | Imputed Feeling Temperature | Dynamic Feature Engineering
A4: Instant | B4: Date | C4: Season | D4: Season_Name | E4: Year | F4: Month | G4: Hour | H4: Holiday | I4: Weekday | J4: Weekday_Name | K4: Day_Type | L4: Rush_Hour | M4: Weather_Sit | N4: Weather_Desc | O4: Temp_Norm | P4: Atemp_Raw | Q4: Atemp_Cleaned | R4: Imputation_Flag | S4: Humidity | T4: Windspeed | U4: Casual | V4: Registered | W4: Total_Count | X4: Casual_Share | Y4: Registered_Share | Z4: Demand_Level | AA4: Hour_Format | AB4: Date_Year | AC4: Date_Month_Text | AD4: Date_Length | AE4: Date_Left_Yr | AF4: Date_Right_Day
A5: 1 | B5: 2011-01-01 | C5: 1 | D5: =VLOOKUP(C5, Lookups_Metadata!$A$4:$B$7, 2, FALSE()) -> Spring | E5: 0 | F5: 1 | G5: 0 | H5: =FALSE() -> FALSE | I5: 6 | J5: =INDEX(Lookups_Metadata!$E$4:$E$10, MATCH(I5, Lookups_Metadata!$D$4:$D$10, 0)) -> Saturday | K5: =IF(H5=TRUE(), "Holiday", IF(OR(I5=0, I5=6), "Weekend", "Weekday")) -> Weekend | L5: =IF(AND(K5="Weekday", OR(AND(G5>=7, G5<=9), AND(G5>=17, G5<=19))), "Peak Commute", "Off-Peak") -> Off-Peak | M5: 1 | N5: =VLOOKUP(M5, Lookups_Metadata!$G$4:$H$7, 2, FALSE()) -> Clear / Few Clouds | O5: 0.24 | P5: 0.2879 | Q5: =IF(OR(P5="", ISBLANK(P5)), ROUND(0.9367*O5+0.0175, 4), P5) -> 0.2879 | R5: =IF(OR(P5="", ISBLANK(P5)), "Imputed (Regression/Trend)", "Original") -> Original | S5: 0.81 | T5: 0 | U5: 3 | V5: 13 | W5: =U5+V5 -> 16 | X5: =U5/W5 -> 0.1875 | Y5: =V5/W5 -> 0.8125 | Z5: =IF(W5>=150, "High Demand", IF(W5>=50, "Moderate Demand", "Low Demand")) -> Low Demand | AA5: =TEXT(G5, "00") & ":00" -> 00:00 | AB5: =YEAR(B5) -> 2011 | AC5: =TEXT(B5, "mmmm") -> January | AD5: =LEN(TEXT(B5, "YYYY-MM-DD")) -> 10 | AE5: =LEFT(TEXT(B5, "YYYY-MM-DD"), 4) -> 2011 | AF5: =RIGHT(TEXT(B5, "YYYY-MM-DD"), 2) -> 01
A6: 2 | B6: 2011-01-01 | C6: 1 | D6: =VLOOKUP(C6, Lookups_Metadata!$A$4:$B$7, 2, FALSE()) -> Spring | E6: 0 | F6: 1 | G6: 1 | H6: =FALSE() -> FALSE | I6: 6 | J6: =INDEX(Lookups_Metadata!$E$4:$E$10, MATCH(I6, Lookups_Metadata!$D$4:$D$10, 0)) -> Saturday | K6: =IF(H6=TRUE(), "Holiday", IF(OR(I6=0, I6=6), "Weekend", "Weekday")) -> Weekend | L6: =IF(AND(K6="Weekday", OR(AND(G6>=7, G6<=9), AND(G6>=17, G6<=19))), "Peak Commute", "Off-Peak") -> Off-Peak | M6: 1 | N6: =VLOOKUP(M6, Lookups_Metadata!$G$4:$H$7, 2, FALSE()) -> Clear / Few Clouds | O6: 0.22 | P6: 0.2727 | Q6: =IF(OR(P6="", ISBLANK(P6)), ROUND(0.9367*O6+0.0175, 4), P6) -> 0.2727 | R6: =IF(OR(P6="", ISBLANK(P6)), "Imputed (Regression/Trend)", "Original") -> Original | S6: 0.8 | T6: 0 | U6: 8 | V6: 32 | W6: =U6+V6 -> 40 | X6: =U6/W6 -> 0.2 | Y6: =V6/W6 -> 0.8 | Z6: =IF(W6>=150, "High Demand", IF(W6>=50, "Moderate Demand", "Low Demand")) -> Low Demand | AA6: =TEXT(G6, "00") & ":00" -> 01:00 | AB6: =YEAR(B6) -> 2011 | AC6: =TEXT(B6, "mmmm") -> January | AD6: =LEN(TEXT(B6, "YYYY-MM-DD")) -> 10 | AE6: =LEFT(TEXT(B6, "YYYY-MM-DD"), 4) -> 2011 | AF6: =RIGHT(TEXT(B6, "YYYY-MM-DD"), 2) -> 01
A7: 3 | B7: 2011-01-01 | C7: 1 | D7: =VLOOKUP(C7, Lookups_Metadata!$A$4:$B$7, 2, FALSE()) -> Spring | E7: 0 | F7: 1 | G7: 2 | H7: =FALSE() -> FALSE | I7: 6 | J7: =INDEX(Lookups_Metadata!$E$4:$E$10, MATCH(I7, Lookups_Metadata!$D$4:$D$10, 0)) -> Saturday | K7: =IF(H7=TRUE(), "Holiday", IF(OR(I7=0, I7=6), "Weekend", "Weekday")) -> Weekend | L7: =IF(AND(K7="Weekday", OR(AND(G7>=7, G7<=9), AND(G7>=17, G7<=19))), "Peak Commute", "Off-Peak") -> Off-Peak | M7: 1 | N7: =VLOOKUP(M7, Lookups_Metadata!$G$4:$H$7, 2, FALSE()) -> Clear / Few Clouds | O7: 0.22 | P7: 0.2727 | Q7: =IF(OR(P7="", ISBLANK(P7)), ROUND(0.9367*O7+0.0175, 4), P7) -> 0.2727 | R7: =IF(OR(P7="", ISBLANK(P7)), "Imputed (Regression/Trend)", "Original") -> Original | S7: 0.8 | T7: 0 | U7: 5 | V7: 27 | W7: =U7+V7 -> 32 | X7: =U7/W7 -> 0.15625 | Y7: =V7/W7 -> 0.84375 | Z7: =IF(W7>=150, "High Demand", IF(W7>=50, "Moderate Demand", "Low Demand")) -> Low Demand | AA7: =TEXT(G7, "00") & ":00" -> 02:00 | AB7: =YEAR(B7) -> 2011 | AC7: =TEXT(B7, "mmmm") -> January | AD7: =LEN(TEXT(B7, "YYYY-MM-DD")) -> 10 | AE7: =LEFT(TEXT(B7, "YYYY-MM-DD"), 4) -> 2011 | AF7: =RIGHT(TEXT(B7, "YYYY-MM-DD"), 2) -> 01
A8: 4 | B8: 2011-01-01 | C8: 1 | D8: =VLOOKUP(C8, Lookups_Metadata!$A$4:$B$7, 2, FALSE()) -> Spring | E8: 0 | F8: 1 | G8: 3 | H8: =FALSE() -> FALSE | I8: 6 | J8: =INDEX(Lookups_Metadata!$E$4:$E$10, MATCH(I8, Lookups_Metadata!$D$4:$D$10, 0)) -> Saturday | K8: =IF(H8=TRUE(), "Holiday", IF(OR(I8=0, I8=6), "Weekend", "Weekday")) -> Weekend | L8: =IF(AND(K8="Weekday", OR(AND(G8>=7, G8<=9), AND(G8>=17, G8<=19))), "Peak Commute", "Off-Peak") -> Off-Peak | M8: 1 | N8: =VLOOKUP(M8, Lookups_Metadata!$G$4:$H$7, 2, FALSE()) -> Clear / Few Clouds | O8: 0.24 | P8: 0.2879 | Q8: =IF(OR(P8="", ISBLANK(P8)), ROUND(0.9367*O8+0.0175, 4), P8) -> 0.2879 | R8: =IF(OR(P8="", ISBLANK(P8)), "Imputed (Regression/Trend)", "Original") -> Original | S8: 0.75 | T8: 0 | U8: 3 | V8: 10 | W8: =U8+V8 -> 13 | X8: =U8/W8 -> 0.23076923 | Y8: =V8/W8 -> 0.76923077 | Z8: =IF(W8>=150, "High Demand", IF(W8>=50, "Moderate Demand", "Low Demand")) -> Low Demand | AA8: =TEXT(G8, "00") & ":00" -> 03:00 | AB8: =YEAR(B8) -> 2011 | AC8: =TEXT(B8, "mmmm") -> January | AD8: =LEN(TEXT(B8, "YYYY-MM-DD")) -> 10 | AE8: =LEFT(TEXT(B8, "YYYY-MM-DD"), 4) -> 2011 | AF8: =RIGHT(TEXT(B8, "YYYY-MM-DD"), 2) -> 01
A9: 5 | B9: 2011-01-01 | C9: 1 | D9: =VLOOKUP(C9, Lookups_Metadata!$A$4:$B$7, 2, FALSE()) -> Spring | E9: 0 | F9: 1 | G9: 4 | H9: =FALSE() -> FALSE | I9: 6 | J9: =INDEX(Lookups_Metadata!$E$4:$E$10, MATCH(I9, Lookups_Metadata!$D$4:$D$10, 0)) -> Saturday | K9: =IF(H9=TRUE(), "Holiday", IF(OR(I9=0, I9=6), "Weekend", "Weekday")) -> Weekend | L9: =IF(AND(K9="Weekday", OR(AND(G9>=7, G9<=9), AND(G9>=17, G9<=19))), "Peak Commute", "Off-Peak") -> Off-Peak | M9: 1 | N9: =VLOOKUP(M9, Lookups_Metadata!$G$4:$H$7, 2, FALSE()) -> Clear / Few Clouds | O9: 0.24 | P9: 0.2879 | Q9: =IF(OR(P9="", ISBLANK(P9)), ROUND(0.9367*O9+0.0175, 4), P9) -> 0.2879 | R9: =IF(OR(P9="", ISBLANK(P9)), "Imputed (Regression/Trend)", "Original") -> Original | S9: 0.75 | T9: 0 | U9: 0 | V9: 1 | W9: =U9+V9 -> 1 | X9: =U9/W9 -> 0 | Y9: =V9/W9 -> 1 | Z9: =IF(W9>=150, "High Demand", IF(W9>=50, "Moderate Demand", "Low Demand")) -> Low Demand | AA9: =TEXT(G9, "00") & ":00" -> 04:00 | AB9: =YEAR(B9) -> 2011 | AC9: =TEXT(B9, "mmmm") -> January | AD9: =LEN(TEXT(B9, "YYYY-MM-DD")) -> 10 | AE9: =LEFT(TEXT(B9, "YYYY-MM-DD"), 4) -> 2011 | AF9: =RIGHT(TEXT(B9, "YYYY-MM-DD"), 2) -> 01
A10: 6 | B10: 2011-01-01 | C10: 1 | D10: =VLOOKUP(C10, Lookups_Metadata!$A$4:$B$7, 2, FALSE()) -> Spring | E10: 0 | F10: 1 | G10: 5 | H10: =FALSE() -> FALSE | I10: 6 | J10: =INDEX(Lookups_Metadata!$E$4:$E$10, MATCH(I10, Lookups_Metadata!$D$4:$D$10, 0)) -> Saturday | K10: =IF(H10=TRUE(), "Holiday", IF(OR(I10=0, I10=6), "Weekend", "Weekday")) -> Weekend | L10: =IF(AND(K10="Weekday", OR(AND(G10>=7, G10<=9), AND(G10>=17, G10<=19))), "Peak Commute", "Off-Peak") -> Off-Peak | M10: 2 | N10: =VLOOKUP(M10, Lookups_Metadata!$G$4:$H$7, 2, FALSE()) -> Mist / Cloudy | O10: 0.24 | P10: 0.2576 | Q10: =IF(OR(P10="", ISBLANK(P10)), ROUND(0.9367*O10+0.0175, 4), P10) -> 0.2576 | R10: =IF(OR(P10="", ISBLANK(P10)), "Imputed (Regression/Trend)", "Original") -> Original | S10: 0.75 | T10: 0.0896 | U10: 0 | V10: 1 | W10: =U10+V10 -> 1 | X10: =U10/W10 -> 0 | Y10: =V10/W10 -> 1 | Z10: =IF(W10>=150, "High Demand", IF(W10>=50, "Moderate Demand", "Low Demand")) -> Low Demand | AA10: =TEXT(G10, "00") & ":00" -> 05:00 | AB10: =YEAR(B10) -> 2011 | AC10: =TEXT(B10, "mmmm") -> January | AD10: =LEN(TEXT(B10, "YYYY-MM-DD")) -> 10 | AE10: =LEFT(TEXT(B10, "YYYY-MM-DD"), 4) -> 2011 | AF10: =RIGHT(TEXT(B10, "YYYY-MM-DD"), 2) -> 01
A11: 7 | B11: 2011-01-01 | C11: 1 | D11: =VLOOKUP(C11, Lookups_Metadata!$A$4:$B$7, 2, FALSE()) -> Spring | E11: 0 | F11: 1 | G11: 6 | H11: =FALSE() -> FALSE | I11: 6 | J11: =INDEX(Lookups_Metadata!$E$4:$E$10, MATCH(I11, Lookups_Metadata!$D$4:$D$10, 0)) -> Saturday | K11: =IF(H11=TRUE(), "Holiday", IF(OR(I11=0, I11=6), "Weekend", "Weekday")) -> Weekend | L11: =IF(AND(K11="Weekday", OR(AND(G11>=7, G11<=9), AND(G11>=17, G11<=19))), "Peak Commute", "Off-Peak") -> Off-Peak | M11: 1 | N11: =VLOOKUP(M11, Lookups_Metadata!$G$4:$H$7, 2, FALSE()) -> Clear / Few Clouds | O11: 0.22 | P11: 0.2727 | Q11: =IF(OR(P11="", ISBLANK(P11)), ROUND(0.9367*O11+0.0175, 4), P11) -> 0.2727 | R11: =IF(OR(P11="", ISBLANK(P11)), "Imputed (Regression/Trend)", "Original") -> Original | S11: 0.8 | T11: 0 | U11: 2 | V11: 0 | W11: =U11+V11 -> 2 | X11: =U11/W11 -> 1 | Y11: =V11/W11 -> 0 | Z11: =IF(W11>=150, "High Demand", IF(W11>=50, "Moderate Demand", "Low Demand")) -> Low Demand | AA11: =TEXT(G11, "00") & ":00" -> 06:00 | AB11: =YEAR(B11) -> 2011 | AC11: =TEXT(B11, "mmmm") -> January | AD11: =LEN(TEXT(B11, "YYYY-MM-DD")) -> 10 | AE11: =LEFT(TEXT(B11, "YYYY-MM-DD"), 4) -> 2011 | AF11: =RIGHT(TEXT(B11, "YYYY-MM-DD"), 2) -> 01
A12: 8 | B12: 2011-01-01 | C12: 1 | D12: =VLOOKUP(C12, Lookups_Metadata!$A$4:$B$7, 2, FALSE()) -> Spring | E12: 0 | F12: 1 | G12: 7 | H12: =FALSE() -> FALSE | I12: 6 | J12: =INDEX(Lookups_Metadata!$E$4:$E$10, MATCH(I12, Lookups_Metadata!$D$4:$D$10, 0)) -> Saturday | K12: =IF(H12=TRUE(), "Holiday", IF(OR(I12=0, I12=6), "Weekend", "Weekday")) -> Weekend | L12: =IF(AND(K12="Weekday", OR(AND(G12>=7, G12<=9), AND(G12>=17, G12<=19))), "Peak Commute", "Off-Peak") -> Off-Peak | M12: 1 | N12: =VLOOKUP(M12, Lookups_Metadata!$G$4:$H$7, 2, FALSE()) -> Clear / Few Clouds | O12: 0.2 | P12: 0.2576 | Q12: =IF(OR(P12="", ISBLANK(P12)), ROUND(0.9367*O12+0.0175, 4), P12) -> 0.2576 | R12: =IF(OR(P12="", ISBLANK(P12)), "Imputed (Regression/Trend)", "Original") -> Original | S12: 0.86 | T12: 0 | U12: 1 | V12: 2 | W12: =U12+V12 -> 3 | X12: =U12/W12 -> 0.33333333 | Y12: =V12/W12 -> 0.66666667 | Z12: =IF(W12>=150, "High Demand", IF(W12>=50, "Moderate Demand", "Low Demand")) -> Low Demand | AA12: =TEXT(G12, "00") & ":00" -> 07:00 | AB12: =YEAR(B12) -> 2011 | AC12: =TEXT(B12, "mmmm") -> January | AD12: =LEN(TEXT(B12, "YYYY-MM-DD")) -> 10 | AE12: =LEFT(TEXT(B12, "YYYY-MM-DD"), 4) -> 2011 | AF12: =RIGHT(TEXT(B12, "YYYY-MM-DD"), 2) -> 01
A13: 9 | B13: 2011-01-01 | C13: 1 | D13: =VLOOKUP(C13, Lookups_Metadata!$A$4:$B$7, 2, FALSE()) -> Spring | E13: 0 | F13: 1 | G13: 8 | H13: =FALSE() -> FALSE | I13: 6 | J13: =INDEX(Lookups_Metadata!$E$4:$E$10, MATCH(I13, Lookups_Metadata!$D$4:$D$10, 0)) -> Saturday | K13: =IF(H13=TRUE(), "Holiday", IF(OR(I13=0, I13=6), "Weekend", "Weekday")) -> Weekend | L13: =IF(AND(K13="Weekday", OR(AND(G13>=7, G13<=9), AND(G13>=17, G13<=19))), "Peak Commute", "Off-Peak") -> Off-Peak | M13: 1 | N13: =VLOOKUP(M13, Lookups_Metadata!$G$4:$H$7, 2, FALSE()) -> Clear / Few Clouds | O13: 0.24 | Q13: =IF(OR(P13="", ISBLANK(P13)), ROUND(0.9367*O13+0.0175, 4), P13) -> 0.2423 | R13: =IF(OR(P13="", ISBLANK(P13)), "Imputed (Regression/Trend)", "Original") -> Imputed (Regression/Trend) | S13: 0.75 | T13: 0 | U13: 1 | V13: 7 | W13: =U13+V13 -> 8 | X13: =U13/W13 -> 0.125 | Y13: =V13/W13 -> 0.875 | Z13: =IF(W13>=150, "High Demand", IF(W13>=50, "Moderate Demand", "Low Demand")) -> Low Demand | AA13: =TEXT(G13, "00") & ":00" -> 08:00 | AB13: =YEAR(B13) -> 2011 | AC13: =TEXT(B13, "mmmm") -> January | AD13: =LEN(TEXT(B13, "YYYY-MM-DD")) -> 10 | AE13: =LEFT(TEXT(B13, "YYYY-MM-DD"), 4) -> 2011 | AF13: =RIGHT(TEXT(B13, "YYYY-MM-DD"), 2) -> 01
A14: 10 | B14: 2011-01-01 | C14: 1 | D14: =VLOOKUP(C14, Lookups_Metadata!$A$4:$B$7, 2, FALSE()) -> Spring | E14: 0 | F14: 1 | G14: 9 | H14: =FALSE() -> FALSE | I14: 6 | J14: =INDEX(Lookups_Metadata!$E$4:$E$10, MATCH(I14, Lookups_Metadata!$D$4:$D$10, 0)) -> Saturday | K14: =IF(H14=TRUE(), "Holiday", IF(OR(I14=0, I14=6), "Weekend", "Weekday")) -> Weekend | L14: =IF(AND(K14="Weekday", OR(AND(G14>=7, G14<=9), AND(G14>=17, G14<=19))), "Peak Commute", "Off-Peak") -> Off-Peak | M14: 1 | N14: =VLOOKUP(M14, Lookups_Metadata!$G$4:$H$7, 2, FALSE()) -> Clear / Few Clouds | O14: 0.32 | P14: 0.3485 | Q14: =IF(OR(P14="", ISBLANK(P14)), ROUND(0.9367*O14+0.0175, 4), P14) -> 0.3485 | R14: =IF(OR(P14="", ISBLANK(P14)), "Imputed (Regression/Trend)", "Original") -> Original | S14: 0.76 | T14: 0 | U14: 8 | V14: 6 | W14: =U14+V14 -> 14 | X14: =U14/W14 -> 0.57142857 | Y14: =V14/W14 -> 0.42857143 | Z14: =IF(W14>=150, "High Demand", IF(W14>=50, "Moderate Demand", "Low Demand")) -> Low Demand | AA14: =TEXT(G14, "00") & ":00" -> 09:00 | AB14: =YEAR(B14) -> 2011 | AC14: =TEXT(B14, "mmmm") -> January | AD14: =LEN(TEXT(B14, "YYYY-MM-DD")) -> 10 | AE14: =LEFT(TEXT(B14, "YYYY-MM-DD"), 4) -> 2011 | AF14: =RIGHT(TEXT(B14, "YYYY-MM-DD"), 2) -> 01
A15: 11 | B15: 2011-01-01 | C15: 1 | D15: =VLOOKUP(C15, Lookups_Metadata!$A$4:$B$7, 2, FALSE()) -> Spring | E15: 0 | F15: 1 | G15: 10 | H15: =FALSE() -> FALSE | I15: 6 | J15: =INDEX(Lookups_Metadata!$E$4:$E$10, MATCH(I15, Lookups_Metadata!$D$4:$D$10, 0)) -> Saturday | K15: =IF(H15=TRUE(), "Holiday", IF(OR(I15=0, I15=6), "Weekend", "Weekday")) -> Weekend | L15: =IF(AND(K15="Weekday", OR(AND(G15>=7, G15<=9), AND(G15>=17, G15<=19))), "Peak Commute", "Off-Peak") -> Off-Peak | M15: 1 | N15: =VLOOKUP(M15, Lookups_Metadata!$G$4:$H$7, 2, FALSE()) -> Clear / Few Clouds | O15: 0.38 | P15: 0.3939 | Q15: =IF(OR(P15="", ISBLANK(P15)), ROUND(0.9367*O15+0.0175, 4), P15) -> 0.3939 | R15: =IF(OR(P15="", ISBLANK(P15)), "Imputed (Regression/Trend)", "Original") -> Original | S15: 0.76 | T15: 0.2537 | U15: 12 | V15: 24 | W15: =U15+V15 -> 36 | X15: =U15/W15 -> 0.33333333 | Y15: =V15/W15 -> 0.66666667 | Z15: =IF(W15>=150, "High Demand", IF(W15>=50, "Moderate Demand", "Low Demand")) -> Low Demand | AA15: =TEXT(G15, "00") & ":00" -> 10:00 | AB15: =YEAR(B15) -> 2011 | AC15: =TEXT(B15, "mmmm") -> January | AD15: =LEN(TEXT(B15, "YYYY-MM-DD")) -> 10 | AE15: =LEFT(TEXT(B15, "YYYY-MM-DD"), 4) -> 2011 | AF15: =RIGHT(TEXT(B15, "YYYY-MM-DD"), 2) -> 01
A16: 12 | B16: 2011-01-01 | C16: 1 | D16: =VLOOKUP(C16, Lookups_Metadata!$A$4:$B$7, 2, FALSE()) -> Spring | E16: 0 | F16: 1 | G16: 11 | H16: =FALSE() -> FALSE | I16: 6 | J16: =INDEX(Lookups_Metadata!$E$4:$E$10, MATCH(I16, Lookups_Metadata!$D$4:$D$10, 0)) -> Saturday | K16: =IF(H16=TRUE(), "Holiday", IF(OR(I16=0, I16=6), "Weekend", "Weekday")) -> Weekend | L16: =IF(AND(K16="Weekday", OR(AND(G16>=7, G16<=9), AND(G16>=17, G16<=19))), "Peak Commute", "Off-Peak") -> Off-Peak | M16: 1 | N16: =VLOOKUP(M16, Lookups_Metadata!$G$4:$H$7, 2, FALSE()) -> Clear / Few Clouds | O16: 0.36 | P16: 0.3333 | Q16: =IF(OR(P16="", ISBLANK(P16)), ROUND(0.9367*O16+0.0175, 4), P16) -> 0.3333 | R16: =IF(OR(P16="", ISBLANK(P16)), "Imputed (Regression/Trend)", "Original") -> Original | S16: 0.81 | T16: 0.2836 | U16: 26 | V16: 30 | W16: =U16+V16 -> 56 | X16: =U16/W16 -> 0.46428571 | Y16: =V16/W16 -> 0.53571429 | Z16: =IF(W16>=150, "High Demand", IF(W16>=50, "Moderate Demand", "Low Demand")) -> Moderate Demand | AA16: =TEXT(G16, "00") & ":00" -> 11:00 | AB16: =YEAR(B16) -> 2011 | AC16: =TEXT(B16, "mmmm") -> January | AD16: =LEN(TEXT(B16, "YYYY-MM-DD")) -> 10 | AE16: =LEFT(TEXT(B16, "YYYY-MM-DD"), 4) -> 2011 | AF16: =RIGHT(TEXT(B16, "YYYY-MM-DD"), 2) -> 01
A17: 13 | B17: 2011-01-01 | C17: 1 | D17: =VLOOKUP(C17, Lookups_Metadata!$A$4:$B$7, 2, FALSE()) -> Spring | E17: 0 | F17: 1 | G17: 12 | H17: =FALSE() -> FALSE | I17: 6 | J17: =INDEX(Lookups_Metadata!$E$4:$E$10, MATCH(I17, Lookups_Metadata!$D$4:$D$10, 0)) -> Saturday | K17: =IF(H17=TRUE(), "Holiday", IF(OR(I17=0, I17=6), "Weekend", "Weekday")) -> Weekend | L17: =IF(AND(K17="Weekday", OR(AND(G17>=7, G17<=9), AND(G17>=17, G17<=19))), "Peak Commute", "Off-Peak") -> Off-Peak | M17: 1 | N17: =VLOOKUP(M17, Lookups_Metadata!$G$4:$H$7, 2, FALSE()) -> Clear / Few Clouds | O17: 0.42 | P17: 0.4242 | Q17: =IF(OR(P17="", ISBLANK(P17)), ROUND(0.9367*O17+0.0175, 4), P17) -> 0.4242 | R17: =IF(OR(P17="", ISBLANK(P17)), "Imputed (Regression/Trend)", "Original") -> Original | S17: 0.77 | T17: 0.2836 | U17: 29 | V17: 55 | W17: =U17+V17 -> 84 | X17: =U17/W17 -> 0.3452381 | Y17: =V17/W17 -> 0.6547619 | Z17: =IF(W17>=150, "High Demand", IF(W17>=50, "Moderate Demand", "Low Demand")) -> Moderate Demand | AA17: =TEXT(G17, "00") & ":00" -> 12:00 | AB17: =YEAR(B17) -> 2011 | AC17: =TEXT(B17, "mmmm") -> January | AD17: =LEN(TEXT(B17, "YYYY-MM-DD")) -> 10 | AE17: =LEFT(TEXT(B17, "YYYY-MM-DD"), 4) -> 2011 | AF17: =RIGHT(TEXT(B17, "YYYY-MM-DD"), 2) -> 01
A18: 14 | B18: 2011-01-01 | C18: 1 | D18: =VLOOKUP(C18, Lookups_Metadata!$A$4:$B$7, 2, FALSE()) -> Spring | E18: 0 | F18: 1 | G18: 13 | H18: =FALSE() -> FALSE | I18: 6 | J18: =INDEX(Lookups_Metadata!$E$4:$E$10, MATCH(I18, Lookups_Metadata!$D$4:$D$10, 0)) -> Saturday | K18: =IF(H18=TRUE(), "Holiday", IF(OR(I18=0, I18=6), "Weekend", "Weekday")) -> Weekend | L18: =IF(AND(K18="Weekday", OR(AND(G18>=7, G18<=9), AND(G18>=17, G18<=19))), "Peak Commute", "Off-Peak") -> Off-Peak | M18: 2 | N18: =VLOOKUP(M18, Lookups_Metadata!$G$4:$H$7, 2, FALSE()) -> Mist / Cloudy | O18: 0.46 | P18: 0.4545 | Q18: =IF(OR(P18="", ISBLANK(P18)), ROUND(0.9367*O18+0.0175, 4), P18) -> 0.4545 | R18: =IF(OR(P18="", ISBLANK(P18)), "Imputed (Regression/Trend)", "Original") -> Original | S18: 0.72 | T18: 0.2985 | U18: 47 | V18: 47 | W18: =U18+V18 -> 94 | X18: =U18/W18 -> 0.5 | Y18: =V18/W18 -> 0.5 | Z18: =IF(W18>=150, "High Demand", IF(W18>=50, "Moderate Demand", "Low Demand")) -> Moderate Demand | AA18: =TEXT(G18, "00") & ":00" -> 13:00 | AB18: =YEAR(B18) -> 2011 | AC18: =TEXT(B18, "mmmm") -> January | AD18: =LEN(TEXT(B18, "YYYY-MM-DD")) -> 10 | AE18: =LEFT(TEXT(B18, "YYYY-MM-DD"), 4) -> 2011 | AF18: =RIGHT(TEXT(B18, "YYYY-MM-DD"), 2) -> 01
